Workbook

Sheet Shipping Details
A1: SHIPPING DETAILS
A2: 20 FOOT CONTAINER CAPACITY 9 PALLET FOR 2 MODULES - 120x105x215cm TOTAL: 18 MODULES | B2: 40 FOOT CONTAINER CAPACITY 21 PALLET FOR 2 MODULES - 120x105x215cm TOTAL: 42 MODULES

Sheet QUOT01 A-V1
A1: HEADER IF APPLICABLE | H1: BACK-OFFICE COMERCIAL
A2: Project image | B2: Project Code | C2: Description | D2: Quantity | E2: Unit Price | F2: Extended Price | G2: Prorrating | H2: % Comision | I2: 0
B3: 15931-B | C3: TOPE DE TOPE ENCANTO – TOY SMART Estructura Metálica + Pintura al horno + Lámina de Cartón + Vinilo adhesivo + impresión digital + Niveladores. | D3: 1 | E3: =IF(I3>0, I3 / (1 - $I$2), 0) -> 100 | F3: =E3*D3 -> 100 | G3: =F3/$F$15 -> 0.5 | H3: Pecio Base | I3: 100
D4: 0 | E4: =IF(I4>0, I4 / (1 - $I$2), 0) -> 0 | F4: =E4*D4 -> 0 | G4: =F4/$F$15 -> 0 | H4: Pecio Base | I4: 0
D5: 0 | E5: =IF(I5>0, I5 / (1 - $I$2), 0) -> 0 | F5: =E5*D5 -> 0 | G5: =F5/$F$15 -> 0 | H5: Pecio Base | I5: 0
A6: TOTAL EXWORKS PRICE (USD) | F6: =SUM(F3:F5) -> 100 | G6: =F6/$F$15 -> 0.5 | H6: Total Comision | I6: =IF(F6>0, F6 * $I$2, 0) -> 0
A7: SHIPPING DETAILS | D7: SHIPPING MODE | E7: AIR / LAND | F7: 100 | G7: =F7/$F$15 -> 0.5
E8: SEA | F8: 0 | G8: =F8/$F$15 -> 0
A9: INSURANCE | F9: 0 | G9: =F9/$F$15 -> 0
A10: DUTY | E10: 0 | F10: 0 | G10: =F10/$F$15 -> 0
A11: TAXES | E11: 0 | F11: 0 | G11: =F11/$F$15 -> 0
A12: COSTS AT ORIGIN | F12: 0 | G12: =F12/$F$15 -> 0
A13: COSTS AT DESTINATION | F13: 0 | G13: =F13/$F$15 -> 0
A14: CONSOLIDATED EXPORT COST | F14: 0 | G14: =F14/$F$15 -> 0
A15: INCOTERM: | C15: CIF + DESTINATION PRICE (USD) | F15: =SUM(F6:F14) -> 200 | G15: =SUM(G6:G14) -> 1
A16: PAY UP TO DATE / PAY IN ADVANCE: | E16: 0 | F16: =F15*E16+F15 -> 200
A17: PAYMENT IN 30 DAYS: | E17: 0.03 | F17: =F15*E17+F15 -> 206
A18: PAYMENT IN 60 DAYS: | E18: 0.06 | F18: =F15*E18+F15 -> 212
A20: TOTAL SHIPPING COST (USD) | F20: =SUM(F7:F14) -> 100 | G20: =F20/F15 -> 0.5
A22: Quantity | B22: =+SUM(D3:$D$6) -> 1 | C22: =+((F15-F28)-F6)/B22 -> 60 | D22: DIFERENCIA DE VALIDACION | E22: =+F29-F15 -> 0 | F22: =E22/$F$6 -> 0
A23: =A1 -> HEADER IF APPLICABLE
A24: Project image | B24: Project Code | C24: Description | D24: Quantity | E24: Unit Price | F24: Extended Price
A25: I | B25: 15931-B | C25: TOPE DE TOPE ENCANTO – TOY SMART Estructura Metálica + Pintura al horno + Lámina de Cartón + Vinilo adhesivo + impresión digital + Niveladores. | D25: =+D3 -> 1 | E25: =IF(D25>0,ROUND(SUM(E3+$C$22),0),0) -> 160 | F25: =E25*D25 -> 160 | G25: =F25/$F$15 -> 0.8
D26: =+D4 -> 0 | E26: =IF(D26>0,ROUND(SUM(E4+$C$22),0),0) -> 0 | F26: =E26*D26 -> 0 | G26: =F26/$F$15 -> 0
D27: =+D5 -> 0 | E27: =IF(D27>0,ROUND(SUM(E5+$C$22),0),0) -> 0 | F27: =E27*D27 -> 0 | G27: =F27/$F$15 -> 0
A28: BEST SHIPPING COST: | D28: 1 | E28: =ROUND(F15*G28,0) -> 40 | F28: =E28*D28 -> 40 | G28: 0.2
A29: TOTAL DDP PRICE (USD) | F29: =SUM(F25:F28) -> 200 | G29: =F29/$F$15 -> 1
A31: Note: Applicable taxes are not included in this quotation and will be reflected on the final invoice based on the delivery address.

Sheet QUOT02 A-V1
A1: 15970 A - PORTAPRECIO EN ACRILICO | G1: BACK-OFFICE COMERCIAL
A2: IMAGE
A3: Description | B3: Quantity | C3: Unit Price | E3: Extended Price | F3: Prorrating | G3: % Comision | H3: 0
B4: 10 | C4: =IF(H4>0, H4 / (1 - $H$3), 0) -> 10 | E4: =C4*B4 -> 100 | F4: =E4/$E$7 -> 1 | G4: Pecio Base | H4: 10
B5: 0 | C5: =IF(H5>0, H5 / (1 - $H$3), 0) -> 0 | E5: =C5*B5 -> 0 | F5: =E5/$E$7 -> 0 | G5: Pecio Base | H5: 0
B6: 0 | C6: =IF(H6>0, H6 / (1 - $H$3), 0) -> 0 | E6: =C6*B6 -> 0 | F6: =E6/$E$7 -> 0 | G6: Pecio Base | H6: 0
A7: TOTAL EXWORKS PRICE (USD) | E7: =SUM(E4:E6) -> 100 | F7: =E7/$E$16 -> 0.059701493 | G7: Total Comision | H7: =IF(E7>0, E7 * H3, 0) -> 0
A8: SHIPPING DETAILS | B8: FREIGHT SHIPPING MODE | D8: AIR / LAND | E8: 1000 | F8: =E8/$E$16 -> 0.59701493
D9: SEA | E9: 0 | F9: =E9/$E$16 -> 0
A10: INSURANCE | E10: 75 | F10: =E10/$E$16 -> 0.044776119
A11: DUTY | D11: 0 | E11: 0 | F11: =E11/$E$16 -> 0
A12: TAXES | D12: 0 | E12: 0 | F12: =E12/$E$16 -> 0
A13: COSTS AT ORIGIN | E13: 500 | F13: =E13/$E$16 -> 0.29850746
A14: COSTS AT DESTINATION | E14: 0 | F14: =E14/$E$16 -> 0
A15: CONSOLIDATED EXPORT COST | E15: 0 | F15: =E15/$E$16 -> 0
B16: CIF + DESTINATION PRICE (USD) | E16: =SUM(E7:E15) -> 1675 | F16: =SUM(F7:F15) -> 1
A18: TOTAL SHIPPING COST (USD) | E18: =SUM(E8:E15) -> 1575 | F18: =E18/E16 -> 0.94029851
A21: Quantity | B21: =+SUM(B4:$B$7) -> 10 | C21: =+((E16-E28)-E7)/B21 -> 124 | D21: DIFERENCIA DE VALIDACION | E21: =+E29-E16 -> 0 | F21: =E21/$E$16 -> 0
A22: =A1 -> 15970 A - PORTAPRECIO EN ACRILICO
A23: IMAGE
A24: Description | B24: Quantity | C24: Unit Price | E24: Extended Price
B25: =+B4 -> 10 | C25: =IF(B25>0, ROUND(C4+$C$21, 0), 0) -> 134 | E25: =C25*B25 -> 1340 | F25: =E25/$E$16 -> 0.8
B26: =+B5 -> 0 | C26: =IF(B26>0, ROUND(C5+$C$21, 0), 0) -> 0 | E26: =C26*B26 -> 0 | F26: =E26/$E$16 -> 0
B27: =+B6 -> 0 | C27: =IF(B27>0, ROUND(C6+$C$21, 0), 0) -> 0 | E27: =C27*B27 -> 0 | F27: =E27/$E$16 -> 0
A28: BEST SHIPPING COST: | B28: 1 | C28: =ROUND(E16*F28,0) -> 335 | E28: =C28*B28 -> 335 | F28: 0.2
A29: TOTAL DDP PRICE (USD) | E29: =SUM(E25:E28) -> 1675 | F29: =E29/$E$16 -> 1
A31: Note: Applicable taxes are not included in this quotation and will be reflected on the final invoice based on the delivery address.

Sheet COT01 A-V1
A1: TITULO SI APLICA
A2: Imagen | B2: Codigo de proyecto | C2: Descripcion | D2: Cantidad | E2: Precio unitario | F2: Precio sub total
B3: 15943-A | C3: DECORACION MESA TENDENCIA Lámina de Cartón + Vinilo adhesivo + impresión digital | D3: 6 | E3: 10000 | F3: =E3*D3 -> 60000
D4: 1 | E4: 0 | F4: =E4*D4 -> 0
D5: 1 | E5: 0 | F5: =E5*D5 -> 0
A6: PRECIO TOTAL SIN IVA (COP) | F6: =SUM(F3:F5) -> 60000
A8: Envios + Instalaciones | D8: Cantidad | E8: Precio unitario | F8: Precio sub total
A9: BOGOTA | D9: 4 | E9: 150000 | F9: =E9*D9 -> 600000
A10: BOGOTA | D10: 2 | E10: 400000 | F10: =E10*D10 -> 800000
A11: PRECIO TOTAL SIN IVA (COP) | F11: =SUM(F9:F10) -> 1400000
A13: GRAN TOTAL SIN IVA (COP) | F13: =F11+F6 -> 1460000

Sheet COT02 A-V1
A1: 15970 A - PORTAPRECIO EN ACRILICO
A2: IMAGEN
A3: Descripcion | D3: Cantidad | E3: Precio unitario | G3: Sub Total
D4: 100 | E4: 720 | G4: =E4*D4 -> 72000
D5: 1 | G5: =E5*D5 -> 0
D6: 1 | G6: =E6*D6 -> 0
D7: 1 | G7: =E7*D7 -> 0
A8: PRECIO TOTAL SIN IVA (COP) | G8: =SUM(G4:G7) -> 72000
A10: Envios + Instalacion | D10: Cantidad | E10: Precio unitario | G10: Sub Total
A11: BOGOTA | D11: 1 | E11: 40000 | G11: =E11*D11 -> 40000
A12: MEDELLIN | D12: 1 | E12: 50000 | G12: =E12*D12 -> 50000
A13: PRECIO TOTAL SIN IVA (COP) | G13: =SUM(G11:G12)+G8 -> 162000
A15: GRAN TOTAL SIN IVA (COP) | G15: =G13+G8 -> 234000

Sheet EXP 17000-A-V1
A1: PRESUPUESTO EXPORTACION - Version Sep 2026
A2: No. Proyecto | B2: Cliente: | G2: Ejecutiva encargada:
A3: 17000-A | B3: Nombre del Proyecto: | G3: Diseñador:
B4: Analista de Costos: | G4: Fecha: | K4: 46023
A5: PRESUPUESTO GENERAL
A6: REFERENCIA | D6: CANT | E6: Rango | K6: Rango
E7: 1 | G7: 1 | I7: 1 | K7: =+E7 -> 1 | L7: =+G7 -> 1 | M7: =+I7 -> 1
E8: VALOR UNITARIO | K8: VALOR TOTAL
A9: Materiales mano de obra y procesos de fabricacion
D10: 1 | E10: 0 | G10: 0 | I10: 0 | K10: =E10*D10 -> 0 | L10: =G10*D10 -> 0 | M10: =I10*D10 -> 0
K11: =E11*D11 -> 0 | L11: =G11*D11 -> 0 | M11: =I11*D11 -> 0
K12: =E12*D12 -> 0 | L12: =G12*D12 -> 0 | M12: =I12*D12 -> 0
K13: =E13*D13 -> 0 | L13: =G13*D13 -> 0 | M13: =I13*D13 -> 0
K14: =E14*D14 -> 0 | L14: =G14*D14 -> 0 | M14: =I14*D14 -> 0
K15: =E15*D15 -> 0 | L15: =G15*D15 -> 0 | M15: =I15*D15 -> 0
K16: =E16*D16 -> 0 | L16: =G16*D16 -> 0 | M16: =I16*D16 -> 0
K17: =E17*D17 -> 0 | L17: =G17*D17 -> 0 | M17: =I17*D17 -> 0
K18: =E18*D18 -> 0 | L18: =G18*D18 -> 0 | M18: =I18*D18 -> 0
K19: =E19*D19 -> 0 | L19: =G19*D19 -> 0 | M19: =I19*D19 -> 0
K20: =E20*D20 -> 0 | L20: =G20*D20 -> 0 | M20: =I20*D20 -> 0
K21: =E21*D21 -> 0 | L21: =G21*D21 -> 0 | M21: =I21*D21 -> 0
K22: =E22*D22 -> 0 | L22: =G22*D22 -> 0 | M22: =I22*D22 -> 0
... K32: =E32*D32 -> 0 | L32: =G32*D32 -> 0 | M32: =I32*D32 -> 0
A33: Armado general | D33: 1 | E33: 0 | G33: 0 | I33: 0 | K33: =E33*D33 -> 0 | L33: =G33*D33 -> 0 | M33: =I33*D33 -> 0
A34: Material de empaque | D34: 1 | E34: 0 | G34: 0 | I34: 0 | K34: =E34*D34 -> 0 | L34: =G34*D34 -> 0 | M34: =I34*D34 -> 0
A35: Tranporte local de entrega: Bogota y perimetro urbano (Valor Global) | D35: 0 | E35: 150000 | G35: 200000 | I35: 300000 | K35: =E35*D35/K7 -> 0 | L35: =G35*D35/L7 -> 0 | M35: =I35*D35/M7 -> 0
A36: Productos de comercializacion
A37: Para aplicar valor de comercializacion: | D37: 1 | E37: 0 | G37: 0 | I37: 0 | K37: =+D37*E37 -> 0 | L37: =G37*D37 -> 0 | M37: =I37*D37 -> 0
A38: Para aplicar valor de comercializacion: | D38: 1 | E38: 0 | G38: 0 | I38: 0 | K38: =+D38*E38 -> 0 | L38: =G38*D38 -> 0 | M38: =I38*D38 -> 0
A39: Para aplicar valor de comercializacion: | D39: 1 | E39: 0 | G39: 0 | I39: 0 | K39: =+D39*E39 -> 0 | L39: =G39*D39 -> 0 | M39: =I39*D39 -> 0
A40: OBSERVACIONES | E40: TOTAL COSTOS DIRECTOS DE FABRICACION | K40: =SUM(K9:K35) -> 0 | L40: =SUM(L9:L35) -> 0 | M40: =SUM(M9:M35) -> 0
A41: PROYECTOS DE GRUPO OHLA / NESTLE TENDRAN UN INCREMENTO DEL 5% FEE INTERNO +3% FEE BANCARIO = 8% FEE TOTAL. | E41: Imprevistos | H41: =MAX(ADMIN!$C$2, ADMIN!$D$2 - (((K$40*K$7) / ADMIN!$B$2) * (ADMIN!$D$2 - ADMIN!$C$2))) -> 0.05 | I41: =MAX(ADMIN!$C$2, ADMIN!$D$2 - (((L$40*L$7) / ADMIN!$B$2) * (ADMIN!$D$2 - ADMIN!$C$2))) -> 0.05 | J41: =MAX(ADMIN!$C$2, ADMIN!$D$2 - (((M$40*M$7) / ADMIN!$B$2) * (ADMIN!$D$2 - ADMIN!$C$2))) -> 0.05 | K41: =K40*H41 -> 0 | L41: =L40*I41 -> 0 | M41: =M40*J41 -> 0
E42: Costos Indirectos | H42: =MAX(ADMIN!$C$3, ADMIN!$D$3 - (((K$40*K$7) / ADMIN!$B$3) * (ADMIN!$D$3 - ADMIN!$C$3))) -> 0.15 | I42: =MAX(ADMIN!$C$3, ADMIN!$D$3 - (((L$40*L$7) / ADMIN!$B$3) * (ADMIN!$D$3 - ADMIN!$C$3))) -> 0.15 | J42: =MAX(ADMIN!$C$3, ADMIN!$D$3 - (((M$40*M$7) / ADMIN!$B$3) * (ADMIN!$D$3 - ADMIN!$C$3))) -> 0.15 | K42: =K40*H42 -> 0 | L42: =L40*I42 -> 0 | M42: =M40*J42 -> 0
E43: SUBTOTAL COSTOS DE COMERCIALIZACION | K43: =SUM(K37:K39) -> 0 | L43: =SUM(L37:L39) -> 0 | M43: =SUM(M37:M39) -> 0
E44: Costos Indirectos | H44: =MAX(ADMIN!$C$4, ADMIN!$D$4 - (((K$43*K$7) / ADMIN!$B$4) * (ADMIN!$D$4 - ADMIN!$C$4))) -> 0.05 | I44: =MAX(ADMIN!$C$4, ADMIN!$D$4 - (((L$43*L$7) / ADMIN!$B$4) * (ADMIN!$D$4 - ADMIN!$C$4))) -> 0.05 | J44: =MAX(ADMIN!$C$4, ADMIN!$D$4 - (((M$43*M$7) / ADMIN!$B$4) * (ADMIN!$D$4 - ADMIN!$C$4))) -> 0.05 | K44: =K43*H44 -> 0 | L44: =L43*I44 -> 0 | M44: =M43*J44 -> 0
E45: TOTAL COSTO BRUTO | K45: =SUM(K40:K44) -> 0 | L45: =SUM(L40:L44) -> 0 | M45: =SUM(M40:M44) -> 0
E46: Utilidad Fabricacion | H46: =MAX(ADMIN!$C$6, ADMIN!$D$6 - (((K$40*K$7) / ADMIN!$B$6) * (ADMIN!$D$6 - ADMIN!$C$6))) -> 0.55 | I46: =MAX(ADMIN!$C$6, ADMIN!$D$6 - (((L$40*L$7) / ADMIN!$B$6) * (ADMIN!$D$6 - ADMIN!$C$6))) -> 0.55 | J46: =MAX(ADMIN!$C$6, ADMIN!$D$6 - (((M$40*M$7) / ADMIN!$B$6) * (ADMIN!$D$6 - ADMIN!$C$6))) -> 0.55 | K46: =IF(K40>0, ((K40+K41+K42)/(1-H46)) - (K40+K41+K42), 0) -> 0 | L46: =IF(L40>0, ((L40+L41+L42)/(1-I46)) - (L40+L41+L42), 0) -> 0 | M46: =IF(M40>0, ((M40+M41+M42)/(1-J46)) - (M40+M41+M42), 0) -> 0
E47: Utilidad Comercializacion | H47: =MAX(ADMIN!$C$8, ADMIN!$D$8 - (((K$43*K$7) / ADMIN!$B$8) * (ADMIN!$D$8 - ADMIN!$C$8))) -> 0.35 | I47: =MAX(ADMIN!$C$8, ADMIN!$D$8 - (((L$43*L$7) / ADMIN!$B$8) * (ADMIN!$D$8 - ADMIN!$C$8))) -> 0.35 | J47: =MAX(ADMIN!$C$8, ADMIN!$D$8 - (((M$43*M$7) / ADMIN!$B$8) * (ADMIN!$D$8 - ADMIN!$C$8))) -> 0.35 | K47: =IF(K43>0, ((K43+K44)/(1-H47)) - (K43+K44), 0) -> 0 | L47: =IF(L43>0, ((L43+L44)/(1-I47)) - (L43+L44), 0) -> 0 | M47: =IF(M43>0, ((M43+M44)/(1-J47)) - (M43+M44), 0) -> 0
E48: TOTAL VENTA BRUTO | K48: =IF(K40>0, (K40+K41+K42)/(1-H46), 0) + IF(K43>0, (K43+K44)/(1-H47), 0) -> 0 | L48: =IF(L40>0, (L40+L41+L42)/(1-I46), 0) + IF(L43>0, (L43+L44)/(1-I47), 0) -> 0 | M48: =IF(M40>0, (M40+M41+M42)/(1-J46), 0) + IF(M43>0, (M43+M44)/(1-J47), 0) -> 0
E49: Decuentos / Incrementos | H49: 0 | I49: 0 | J49: 0 | K49: =IF(K51>0, K51 * H49, 0) -> 0 | L49: =IF(L51>0, L51 * I49, 0) -> 0 | M49: =IF(M51>0, M51 * J49, 0) -> 0
...

Sheet NAL 17000-A-V1
A1: PRESUPUESTO NACIONAL - Version Sep 2026
A2: No. Proyecto | B2: Cliente: | G2: Ejecutiva encargada:
A3: 17000-A | B3: Nombre del Proyecto: | G3: Diseñador:
B4: Analista de Costos: | G4: Fecha: | K4: 46023
A5: PRESUPUESTO GENERAL
A6: REFERENCIA | D6: CANT | E6: Rango | K6: Rango
E7: 100 | G7: 200 | I7: 500 | K7: =+E7 -> 100 | L7: =+G7 -> 200 | M7: =+I7 -> 500
E8: VALOR UNITARIO | K8: VALOR TOTAL
A9: Materiales mano de obra y procesos de fabricacion
D10: 1 | E10: 400000 | G10: 350000 | I10: 330000 | K10: =E10*D10 -> 400000 | L10: =G10*D10 -> 350000 | M10: =I10*D10 -> 330000
K11: =E11*D11 -> 0 | L11: =G11*D11 -> 0 | M11: =I11*D11 -> 0
K12: =E12*D12 -> 0 | L12: =G12*D12 -> 0 | M12: =I12*D12 -> 0
K13: =E13*D13 -> 0 | L13: =G13*D13 -> 0 | M13: =I13*D13 -> 0
K14: =E14*D14 -> 0 | L14: =G14*D14 -> 0 | M14: =I14*D14 -> 0
K15: =E15*D15 -> 0 | L15: =G15*D15 -> 0 | M15: =I15*D15 -> 0
K16: =E16*D16 -> 0 | L16: =G16*D16 -> 0 | M16: =I16*D16 -> 0
K17: =E17*D17 -> 0 | L17: =G17*D17 -> 0 | M17: =I17*D17 -> 0
K18: =E18*D18 -> 0 | L18: =G18*D18 -> 0 | M18: =I18*D18 -> 0
K19: =E19*D19 -> 0 | L19: =G19*D19 -> 0 | M19: =I19*D19 -> 0
K20: =E20*D20 -> 0 | L20: =G20*D20 -> 0 | M20: =I20*D20 -> 0
K21: =E21*D21 -> 0 | L21: =G21*D21 -> 0 | M21: =I21*D21 -> 0
K22: =E22*D22 -> 0 | L22: =G22*D22 -> 0 | M22: =I22*D22 -> 0
... K32: =E32*D32 -> 0 | L32: =G32*D32 -> 0 | M32: =I32*D32 -> 0
A33: Armado general | D33: 1 | E33: 0 | G33: 0 | I33: 0 | K33: =E33*D33 -> 0 | L33: =G33*D33 -> 0 | M33: =I33*D33 -> 0
A34: Material de empaque | D34: 1 | E34: 0 | G34: 0 | I34: 0 | K34: =E34*D34 -> 0 | L34: =G34*D34 -> 0 | M34: =I34*D34 -> 0
A35: Tranporte local de entrega: Bogota y perimetro urbano (Valor Global) | D35: 1 | E35: 150000 | G35: 150000 | I35: 150000 | K35: =E35*D35/K7 -> 1500 | L35: =G35*D35/L7 -> 750 | M35: =I35*D35/M7 -> 300
A36: Productos de comercializacion
A37: Para aplicar valor de comercializacion: | D37: 1 | E37: 0 | G37: 0 | I37: 0 | K37: =+D37*E37 -> 0 | L37: =G37*D37 -> 0 | M37: =I37*D37 -> 0
A38: Para aplicar valor de comercializacion: | D38: 1 | E38: 0 | G38: 0 | I38: 0 | K38: =+D38*E38 -> 0 | L38: =G38*D38 -> 0 | M38: =I38*D38 -> 0
A39: Para aplicar valor de comercializacion: | D39: 1 | E39: 0 | G39: 0 | I39: 0 | K39: =+D39*E39 -> 0 | L39: =G39*D39 -> 0 | M39: =I39*D39 -> 0
A40: OBSERVACIONES | E40: TOTAL COSTOS DIRECTOS DE FABRICACION | K40: =SUM(K9:K35) -> 401500 | L40: =SUM(L9:L35) -> 350750 | M40: =SUM(M9:M35) -> 330300
A41: PROYECTOS DE GRUPO OHLA / NESTLE TENDRAN UN INCREMENTO DEL 5% FEE INTERNO +3% FEE BANCARIO = 8% FEE TOTAL. | E41: Imprevistos | H41: =MAX(ADMIN!$C$2, ADMIN!$D$2 - (((K$40*K$7) / ADMIN!$B$2) * (ADMIN!$D$2 - ADMIN!$C$2))) -> 0.043308333 | I41: =MAX(ADMIN!$C$2, ADMIN!$D$2 - (((L$40*L$7) / ADMIN!$B$2) * (ADMIN!$D$2 - ADMIN!$C$2))) -> 0.038308333 | J41: =MAX(ADMIN!$C$2, ADMIN!$D$2 - (((M$40*M$7) / ADMIN!$B$2) * (ADMIN!$D$2 - ADMIN!$C$2))) -> 0.022475 | K41: =K40*H41 -> 17388.296 | L41: =L40*I41 -> 13436.648 | M41: =M40*J41 -> 7423.4925
E42: Costos Indirectos | H42: =MAX(ADMIN!$C$3, ADMIN!$D$3 - (((K$40*K$7) / ADMIN!$B$3) * (ADMIN!$D$3 - ADMIN!$C$3))) -> 0.13884722 | I42: =MAX(ADMIN!$C$3, ADMIN!$D$3 - (((L$40*L$7) / ADMIN!$B$3) * (ADMIN!$D$3 - ADMIN!$C$3))) -> 0.13051389 | J42: =MAX(ADMIN!$C$3, ADMIN!$D$3 - (((M$40*M$7) / ADMIN!$B$3) * (ADMIN!$D$3 - ADMIN!$C$3))) -> 0.104125 | K42: =K40*H42 -> 55747.16 | L42: =L40*I42 -> 45777.747 | M42: =M40*J42 -> 34392.487
E43: SUBTOTAL COSTOS DE COMERCIALIZACION | K43: =SUM(K37:K39) -> 0 | L43: =SUM(L37:L39) -> 0 | M43: =SUM(M37:M39) -> 0
E44: Costos Indirectos | H44: =MAX(ADMIN!$C$4, ADMIN!$D$4 - (((K$43*K$7) / ADMIN!$B$4) * (ADMIN!$D$4 - ADMIN!$C$4))) -> 0.05 | I44: =MAX(ADMIN!$C$4, ADMIN!$D$4 - (((L$43*L$7) / ADMIN!$B$4) * (ADMIN!$D$4 - ADMIN!$C$4))) -> 0.05 | J44: =MAX(ADMIN!$C$4, ADMIN!$D$4 - (((M$43*M$7) / ADMIN!$B$4) * (ADMIN!$D$4 - ADMIN!$C$4))) -> 0.05 | K44: =K43*H44 -> 0 | L44: =L43*I44 -> 0 | M44: =M43*J44 -> 0
E45: TOTAL COSTO BRUTO | K45: =SUM(K40:K44) -> 474635.46 | L45: =SUM(L40:L44) -> 409964.39 | M45: =SUM(M40:M44) -> 372115.98
E46: Utilidad Fabricacion | H46: =MAX(ADMIN!$C$5, ADMIN!$D$5 - (((K$40*K$7) / ADMIN!$B$5) * (ADMIN!$D$5 - ADMIN!$C$5))) -> 0.44423611 | I46: =MAX(ADMIN!$C$5, ADMIN!$D$5 - (((L$40*L$7) / ADMIN!$B$5) * (ADMIN!$D$5 - ADMIN!$C$5))) -> 0.40256944 | J46: =MAX(ADMIN!$C$5, ADMIN!$D$5 - (((M$40*M$7) / ADMIN!$B$5) * (ADMIN!$D$5 - ADMIN!$C$5))) -> 0.270625 | K46: =IF(K40>0, ((K40+K41+K42)/(1-H46)) - (K40+K41+K42), 0) -> 379388.11 | L46: =IF(L40>0, ((L40+L41+L42)/(1-I46)) - (L40+L41+L42), 0) -> 276248.24 | M46: =IF(M40>0, ((M40+M41+M42)/(1-J46)) - (M40+M41+M42), 0) -> 138068.74
E47: Utilidad Comercializacion | H47: =MAX(ADMIN!$C$7, ADMIN!$D$7 - (((K$43*K$7) / ADMIN!$B$7) * (ADMIN!$D$7 - ADMIN!$C$7))) -> 0.3 | I47: =MAX(ADMIN!$C$7, ADMIN!$D$7 - (((L$43*L$7) / ADMIN!$B$7) * (ADMIN!$D$7 - ADMIN!$C$7))) -> 0.3 | J47: =MAX(ADMIN!$C$7, ADMIN!$D$7 - (((M$43*M$7) / ADMIN!$B$7) * (ADMIN!$D$7 - ADMIN!$C$7))) -> 0.3 | K47: =IF(K43>0, ((K43+K44)/(1-H47)) - (K43+K44), 0) -> 0 | L47: =IF(L43>0, ((L43+L44)/(1-I47)) - (L43+L44), 0) -> 0 | M47: =IF(M43>0, ((M43+M44)/(1-J47)) - (M43+M44), 0) -> 0
E48: TOTAL VENTA BRUTO | K48: =IF(K40>0, (K40+K41+K42)/(1-H46), 0) + IF(K43>0, (K43+K44)/(1-H47), 0) -> 854023.56 | L48: =IF(L40>0, (L40+L41+L42)/(1-I46), 0) + IF(L43>0, (L43+L44)/(1-I47), 0) -> 686212.63 | M48: =IF(M40>0, (M40+M41+M42)/(1-J46), 0) + IF(M43>0, (M43+M44)/(1-J47), 0) -> 510184.72
E49: Decuentos / Incrementos | H49: 0 | I49: 0 | J49: 0 | K49: =IF(K51>0, K51 * H49, 0) -> 0 | L49: =IF(L51>0, L51 * I49, 0) -> 0 | M49: =IF(M51>0, M51 * J49, 0) -> 0
...

Sheet ADMIN
A1: Variables | B1: Tope maximo dilusion $ | C1: Tope minimo % | D1: Tope maximo % | E1: Tope venta Max Dto | F1: Com prmedio
A2: Imprevistos fabricacion | B2: 180000000 | C2: 0.02 | D2: 0.05
A3: Costos indirectos fabricacion | B3: 180000000 | C3: 0.1 | D3: 0.15
A4: Costos indirectos comercializacion | B4: 180000000 | C4: 0.02 | D4: 0.05
A5: Utilidad fabricacion nacional | B5: 180000000 | C5: 0.25 | D5: 0.5
A6: Utilidad fabricacion internacional | B6: 180000000 | C6: 0.3 | D6: 0.55
A7: Utilidad comercializacion nacional | B7: 180000000 | C7: 0.15 | D7: 0.3
A8: Utilidad comercializacion internacional | B8: 180000000 | C8: 0.2 | D8: 0.35
A9: Meta Venta nacional | B9: =((E9*(1-F9))*(1-C5))/(1+C2+C3) -> 1.9084821e+08 | E9: 300000000 | F9: 0.05
A10: Meta Venta internacional | B10: =((E10*(1-F10))*(1-C6))/(1+C2+C3) -> 59375000 | E10: 100000000 | F10: 0.05

Sheet Metales
A1: COTIZACION ESTRUCTURAS METALICAS
A3: VIGENCIA FEB DE 2023
B5: REF | C5: CAL 22 | D5: CAL 20 | E5: CAL 18 | F5: CAL 16 | G5: PINTURA | H5: SUBTOTAL | K5: REF | L5: CAL 20 | M5: CAL 18 | N5: CAL 16 | O5: PINTURA | P5: SUBTOTAL | R5: TUBERIA CUADRADA | T5: REF | U5: CAL 22 | V5: CAL 20 | W5: CAL 18 | X5: CAL 16 | Y5: PINTURA | AB5: RECTANGULARES | AC5: REF | AD5: CAL 20 | AE5: CAL 18 | AF5: CAL 16 | AG5: PINTURA
A6: TUBERIA CUADRADA | B6: 1/2" | C6: 0 | D6: 0 | E6: 0 | F6: 0 | G6: =Y6*(C6+D6+E6+F6) -> 0 | H6: =(C6*U6)+(D6*V6)+(E6*W6)+(F6*X6) -> 0 | J6: RECTANGULARES | K6: 12X25 | L6: 0 | M6: 0 | N6: 0 | O6: =AG6*(L6+M6+N6) -> 0 | P6: =L6*AD6+M6*AE6+N6*AF6 -> 0 | T6: 1/2" | V6: 2533 | W6: 3333 | Y6: 800 | AC6: 12X25 | AD6: 3333 | AE6: 4583 | AG6: =0.07*W56 -> 980
B7: 5/8" | C7: 0 | D7: 0 | E7: 0 | F7: 0 | G7: =Y7*(C7+D7+E7+F7) -> 0 | H7: =(C7*U7)+(D7*V7)+(E7*W7)+(F7*X7) -> 0 | K7: 18X32 | L7: 0 | M7: 0 | N7: 0 | O7: =AG7*(L7+M7+N7) -> 0 | P7: =L7*AD7+M7*AE7+N7*AF7 -> 0 | T7: 5/8" | Y7: 800 | AC7: 18X32 | AE7: 6302 | AG7: 750
B8: 3/4" | C8: 0 | D8: 0 | E8: 0 | F8: 0 | G8: =Y8*(C8+D8+E8+F8) -> 0 | H8: =(C8*U8)+(D8*V8)+(E8*W8)+(F8*X8) -> 0 | K8: 20X40 | L8: 0 | M8: 0 | N8: 0 | O8: =AG8*(L8+M8+N8) -> 0 | P8: =L8*AD8+M8*AE8+N8*AF8 -> 0 | T8: 3/4" | V8: 3750 | W8: 4750 | X8: 6000 | Y8: =W56*0.08 -> 1120 | AC8: 20X40 | AD8: 5833 | AE8: 7333 | AF8: 10000 | AG8: =W56*0.12 -> 1680
B9: 7/8" | C9: 0 | D9: 0 | E9: 0 | F9: 0 | G9: =Y9*(C9+D9+E9+F9) -> 0 | H9: =(C9*U9)+(D9*V9)+(E9*W9)+(F9*X9) -> 0 | K9: 25X50 | L9: 0 | M9: 0 | N9: 0 | O9: =AG9*(L9+M9+N9) -> 0 | P9: =L9*AD9+M9*AE9+N9*AF9 -> 0 | T9: 7/8" | Y9: =W56*0.09 -> 1260 | AC9: 25X50 | AD9: 7166 | AE9: 9166 | AF9: 12333 | AG9: =W56*0.15 -> 2100
B10: 1" | C10: 0 | D10: 0 | E10: 0 | F10: 0 | G10: =Y10*(C10+D10+E10+F10) -> 0 | H10: =(C10*U10)+(D10*V10)+(E10*W10)+(F10*X10) -> 0 | K10: 78X38 | L10: 0 | M10: 0 | N10: 0 | O10: =AG10*(L10+M10+N10) -> 0 | P10: =L10*AD10+M10*AE10+N10*AF10 -> 0 | T10: 1" | V10: 4666 | W10: 5833 | X10: 7833 | Y10: =W56*0.1 -> 1400 | AC10: 78X38 | AD10: 10075 | AE10: 11204 | AF10: 12333 | AG10: =W56*0.232 -> 3248
B11: 1-1/8" | C11: 0 | D11: 0 | E11: 0 | F11: 0 | G11: =Y11*(C11+D11+E11+F11) -> 0 | H11: =(C11*U11)+(D11*V11)+(E11*W11)+(F11*X11) -> 0 | K11: OTROS | L11: 0 | M11: 0 | N11: 0 | O11: 0 | P11: =L11+M11+N11 -> 0 | T11: 1-1/8" | Y11: =W56*0.11 -> 1540
B12: 1-1/4" | C12: 0 | D12: 0 | E12: 0 | F12: 0 | G12: =Y12*(C12+D12+E12+F12) -> 0 | H12: =(C12*U12)+(D12*V12)+(E12*W12)+(F12*X12) -> 0 | M12: TOTAL | O12: =SUM(O6:O11) -> 0 | P12: =SUM(P6:P11) -> 0 | T12: 1-1/4" | V12: 6411 | W12: 8333 | Y12: =W56*0.13 -> 1820
B13: 1-1/2" | C13: 0 | D13: 0 | E13: 0 | F13: 0 | G13: =Y13*(C13+D13+E13+F13) -> 0 | H13: =(C13*U13)+(D13*V13)+(E13*W13)+(F13*X13) -> 0 | T13: 1-1/2" | V13: 7166 | W13: 9166 | X13: 12333 | Y13: =W56*0.15 -> 2100
B14: 2" | C14: 0 | D14: 0 | E14: 0 | F14: 0 | G14: =Y14*(C14+D14+E14+F14) -> 0 | H14: =(C14*U14)+(D14*V14)+(E14*W14)+(F14*X14) -> 0 | J14: OVALADOS | K14: REF | L14: CAL 20 | M14: CAL 18 | N14: CAL 16 | O14: PINTURA | P14: SUBTOTAL | T14: 2" | V14: 9166 | W14: 11666 | X14: 15833 | Y14: =W56*0.2 -> 2800 | AB14: OVALADOS | AC14: REF | AD14: CAL 20 | AE14: CAL 18 | AF14: CAL 16 | AG14: PINTURA
B15: 2.5" | C15: 0 | D15: 0 | E15: 0 | F15: 0 | G15: =Y15*(C15+D15+E15+F15) -> 0 | H15: =(C15*U15)+(D15*V15)+(E15*W15)+(F15*X15) -> 0 | K15: 14X28 | L15: 0 | M15: 0 | N15: 0 | O15: =AG15*(N15+M15+L15) -> 0 | P15: =L15*AD15+M15*AE15+N15*AF15 -> 0 | T15: 2.5" | Y15: =W56*0.25 -> 3500 | AC15: 14X28 | AG15: 650
B16: 3" | C16: 0 | D16: 0 | E16: 0 | F16: 0 | G16: =Y16*(C16+D16+E16+F16) -> 0 | H16: =(C16*U16)+(D16*V16)+(E16*W16)+(F16*X16) -> 0 | K16: 25X48 | L16: 0 | M16: 0 | N16: 0 | O16: =AG16*(N16+M16+L16) -> 0 | P16: =L16*AD16+M16*AE16+N16*AF16 -> 0 | T16: 3" | Y16: =W56*0.3 -> 4200 | AC16: 25X48 | AG16: 1300
B17: OTROS | C17: 0 | D17: 0 | E17: 0 | F17: 0 | G17: =Y17*(C17+D17+E17+F17) -> 0 | H17: =(C17*U17)+(D17*V17)+(E17*W17)+(F17*X17) -> 0 | K17: 31X61 | L17: 0 | M17: 0 | N17: 0 | O17: =AG17*(N17+M17+L17) -> 0 | P17: =L17*AD17+M17*AE17+N17*AF17 -> 0 | AC17: 31X61 | AG17: 1820
B18: OTROS | C18: 0 | D18: 0 | E18: 0 | F18: 0 | G18: =Y18*(C18+D18+E18+F18) -> 0 | H18: =(C18*U18)+(D18*V18)+(E18*W18)+(F18*X18) -> 0 | M18: TOTAL | O18: =SUM(O15:O17) -> 0 | P18: =SUM(P15:P17) -> 0
E19: TOTAL | G19: =SUM(G6:G18) -> 0 | H19: =SUM(H6:H18) -> 0
K20: REF | L20: 1/8" | M20: 3/16" | N20: 1/4" | O20: PINTURA | P20: SUBTOTAL | AB20: PLATINAS | AC20: REF | AD20: 1/8" | AE20: 3/16" | AF20: 1/4" | AG20: PINTURA
B21: REF | C21: CAL 22 | D21: CAL 20 | E21: CAL 18 | F21: CAL 16 | G21: PINTURA | H21: SUBTOTAL | J21: PLATINAS | K21: 1/2" | L21: 0 | M21: 0 | N21: 0 | O21: =AG21*(N21+M21+L21) -> 0 | P21: =L21*AD21+M21*AE21+N21*AF21 -> 0 | R21: TUBERIA REDONDA | T21: REF | U21: CAL 22 | V21: CAL 20 | W21: CAL 18 | X21: CAL 16 | Y21: PINTURA | AC21: 1/2" | AD21: 1916 | AG21: 500
A22: TUBERIA REDONDA | B22: 3/8" | C22: 0 | D22: 0 | E22: 0 | F22: 0 | G22: =(F22+E22+D22+C22)*Y22 -> 0 | H22: =(C22*U22+D22*V22+E22*W22+F22*X22) -> 0 | K22: 3/4" | L22: 0 | M22: 0 | N22: 0 | O22: =AG22*(N22+M22+L22) -> 0 | P22: =L22*AD22+M22*AE22+N22*AF22 -> 0 | T22: 3/8" | V22: 3500 | W22: 4400 | Y22: 800 | AC22: 3/4" | AD22: 2941 | AG22: 500
B23: 1/2" | C23: 0 | D23: 0 | E23: 0 | F23: 0 | G23: =(F23+E23+D23+C23)*Y23 -> 0 | H23: =(C23*U23+D23*V23+E23*W23+F23*X23) -> 0 | K23: 1" | L23: 0 | M23: 0 | N23: 0 | O23: =AG23*(N23+M23+L23) -> 0 | P23: =L23*AD23+M23*AE23+N23*AF23 -> 0 | T23: 1/2" | V23: 2333 | W23: 2833 | X23: 3500 | Y23: 800 | AC23: 1" | AD23: 4333 | AG23: =W56*0.05 -> 700
B24: 5/8" | C24: 0 | D24: 0 | E24: 0 | F24: 0 | G24: =(F24+E24+D24+C24)*Y24 -> 0 | H24: =(C24*U24+D24*V24+E24*W24+F24*X24) -> 0 | K24: 1-1/2" | L24: 0 | M24: 0 | N24: 0 | O24: =AG24*(N24+M24+L24) -> 0 | P24: =L24*AD24+M24*AE24+N24*AF24 -> 0 | T24: 5/8" | V24: 2666 | W24: 3500 | X24: 4416 | Y24: 800 | AC24: 1-1/2" | AD24: 6666 | AG24: 600
B25: 3/4" | C25: 0 | D25: 0 | E25: 0 | F25: 0 | G25: =(F25+E25+D25+C25)*Y25 -> 0 | H25: =(C25*U25+D25*V25+E25*W25+F25*X25) -> 0 | K25: 2" | L25: 0 | M25: 0 | N25: 0 | O25: =AG25*(N25+M25+L25) -> 0 | P25: =L25*AD25+M25*AE25+N25*AF25 -> 0 | T25: 3/4" | V25: 3083 | W25: 4083 | X25: 5250 | Y25: 800 | AC25: 2" | AD25: 8666 | AG25: =W56*0.1 -> 1400
B26: 7/8" | C26: 0 | D26: 0 | E26: 0 | F26: 0 | G26: =(F26+E26+D26+C26)*Y26 -> 0 | H26: =(C26*U26+D26*V26+E26*W26+F26*X26) -> 0 | K26: 2-1/2" | L26: 0 | M26: 0 | N26: 0 | O26: =AG26*(N26+M26+L26) -> 0 | P26: =L26*AD26+M26*AE26+N26*AF26 -> 0 | T26: 7/8" | V26: 3750 | W26: 4916 | X26: 7000 | Y26: 800 | AC26: 2-1/2" | AG26: =W56*0.125 -> 1750
B27: 1" | C27: 0 | D27: 0 | E27: 0 | F27: 0 | G27: =(F27+E27+D27+C27)*Y27 -> 0 | H27: =(C27*U27+D27*V27+E27*W27+F27*X27) -> 0 | M27: TOTAL | O27: =SUM(O21:O26) -> 0 | P27: =SUM(P21:P26) -> 0 | T27: 1" | V27: 4166 | W27: 5833 | X27: 7166 | Y27: =W56*0.08 -> 1120
B28: 1-1/8" | C28: 0 | D28: 0 | E28: 0 | F28: 0 | G28: =(F28+E28+D28+C28)*Y28 -> 0 | H28: =(C28*U28+D28*V28+E28*W28+F28*X28) -> 0 | T28: 1-1/8" | V28: 4765 | W28: 6166 | X28: 7282 | Y28: =W56*0.09 -> 1260
B29: 1-1/4" | C29: 0 | D29: 0 | E29: 0 | F29: 0 | G29: =(F29+E29+D29+C29)*Y29 -> 0 | H29: =(C29*U29+D29*V29+E29*W29+F29*X29) -> 0 | K29: REF | L29: 1/8" | M29: 3/16" | N29: 1/4" | O29: PINTURA | P29: SUBTOTAL | T29: 1-1/4" | V29: 5083 | W29: 7000 | X29: 9500 | Y29: =W56*0.1 -> 1400 | AB29: ANGULOS | AC29: REF | AD29: 1/8" | AE29: 3/16" | AF29: 1/4" | AG29: PINTURA
B30: 1-1/2" | C30: 0 | D30: 0 | E30: 0 | F30: 0 | G30: =(F30+E30+D30+C30)*Y30 -> 0 | H30: =(C30*U30+D30*V30+E30*W30+F30*X30) -> 0 | J30: ANGULOS | K30: 1/2" | L30: 0 | M30: 0 | N30: 0 | O30: =AG30*(N30+M30+L30) -> 0 | P30: =L30*AD30+M30*AE30+N30*AF30 -> 0 | T30: 1-1/2" | V30: 6000 | W30: 8333 | X30: 10750 | Y30: =W56*0.12 -> 1680 | AC30: 1/2"
B31: 2" | C31: 0 | D31: 0 | E31: 0 | F31: 0 | G31: =(F31+E31+D31+C31)*Y31 -> 0 | H31: =(C31*U31+D31*V31+E31*W31+F31*X31) -> 0 | K31: 3/4" | L31: 0 | M31: 0 | N31: 0 | O31: =AG31*(N31+M31+L31) -> 0 | P31: =L31*AD31+M31*AE31+N31*AF31 -> 0 | T31: 2" | Y31: =W56*0.16 -> 2240 | AC31: 3/4" | AD31: 4583 | AG31: =W56*0.06 -> 840
B32: 2.5" | C32: 0 | D32: 0 | E32: 0 | F32: 0 | G32: =(F32+E32+D32+C32)*Y32 -> 0 | H32: =(C32*U32+D32*V32+E32*W32+F32*X32) -> 0 | K32: 1" | L32: 0 | M32: 0 | N32: 0 | O32: =AG32*(N32+M32+L32) -> 0 | P32: =L32*AD32+M32*AE32+N32*AF32 -> 0 | T32: 2-1/2" | Y32: =W56*0.2 -> 2800 | AC32: 1" | AD32: 7750 | AG32: =W56*0.075 -> 1050
B33: 3" | C33: 0 | D33: 0 | E33: 0 | F33: 0 | G33: =(F33+E33+D33+C33)*Y33 -> 0 | H33: =(C33*U33+D33*V33+E33*W33+F33*X33) -> 0 | K33: 1-1/2" | L33: 0 | M33: 0 | N33: 0 | O33: =AG33*(N33+M33+L33) -> 0 | P33: =L33*AD33+M33*AE33+N33*AF33 -> 0 | T33: 3" | Y33: =W56*0.23 -> 3220 | AC33: 1-1/2" | AD33: 12500 | AG33: =W56*0.114 -> 1596
B34: OTROS | C34: 0 | D34: 0 | E34: 0 | F34: 0 | G34: =(F34+E34+D34+C34)*Y34 -> 0 | H34: =(C34*U34+D34*V34+E34*W34+F34*X34) -> 0 | K34: 2" | L34: 0 | M34: 0 | N34: 0 | O34: =AG34*(N34+M34+L34) -> 0 | P34: =L34*AD34+M34*AE34+N34*AF34 -> 0 | AC34: 2" | AD34: 16500 | AG34: =W56*0.15 -> 2100
B35: OTROS | C35: 0 | D35: 0 | E35: 0 | F35: 0 | G35: =(F35+E35+D35+C35)*Y35 -> 0 | H35: =(C35*U35+D35*V35+E35*W35+F35*X35) -> 0 | M35: TOTAL | O35: =SUM(O30:O34) -> 0 | P35: =SUM(P30:P34) -> 0
E36: TOTAL | G36: =SUM(G22:G35) -> 0 | H36: =SUM(H22:H35) -> 0 | R36: LAMINA CR | T36: MEDIDA | V36: CAL | W36: VALOR
J37: AALAMBRON | K37: 3 mm | M37: =AE38 -> 0 | N37: 0 | O37: =AF38*N37 -> 0 | P37: =M37*N37 -> 0 | T37: LAMINA CR 120X240 CM | V37: 12 | AB37: AALAMBRON | AC37: REF | AD37: No. | AE37: $ | AF37: PINTURA | AG37: PINTADO
A38: LAMINAS CR | B38: MEDIDA | D38: $ UNITARIO | F38: CANT. | G38: PINTURA | H38: SUBTOTAL | K38: 4 mm | M38: =AE39 -> 783 | N38: 0 | O38: =AF39*N38 -> 0 | P38: =M38*N38 -> 0 | V38: 14 | W38: 300000 | AC38: 3 mm | AD38: 10 | AF38: 400 | AG38: =AF38+AE38 -> 400
D39: 0 | F39: 0 | G39: 0 | H39: =D39*F39 -> 0 | K39: 5 mm | M39: =AE40 -> 1266 | N39: 0 | O39: =AF40*N39 -> 0 | P39: =M39*N39 -> 0 | V39: 16 | W39: 235000 | AC39: 4 mm | AD39: 8 | AE39: 783 | AF39: 500 | AG39: =AF39+AE39 -> 1283
D40: 0 | F40: 0 | G40: 0 | H40: =D40*F40 -> 0 | K40: 6 mm | M40: =AE41 -> 1833 | N40: 0 | O40: =AF41*N40 -> 0 | P40: =M40*N40 -> 0 | V40: 18 | W40: 175000 | AC40: 5 mm | AD40: 6 | AE40: 1266 | AF40: 500 | AG40: =AF40+AE40 -> 1766
D41: 0 | F41: 0 | G41: 0 | H41: =D41*F41 -> 0 | K41: 8 mm | M41: =AE42 -> 3166 | N41: 0 | O41: =AF42*N41 -> 0 | P41: =M41*N41 -> 0 | V41: 20 | W41: 140000 | AC41: 6 mm | AD41: 4 | AE41: 1833 | AF41: 500 | AG41: =AF41+AE41 -> 2333
D42: 0 | F42: 0 | G42: 0 | H42: =D42*F42 -> 0 | M42: TOTAL | O42: =SUM(O37:O41) -> 0 | P42: =SUM(P37:P41) -> 0 | V42: 22 | W42: 122000 | AC42: 8 mm | AD42: 3/8" | AE42: 3166 | AF42: 500 | AG42: =AF42+AE42 -> 3666
...

Sheet Alambron
A2: COTIZACION ALAMBRON
A3: VIGENCIA FEB 2023
A6: 3MM | B6: 4MM | C6: 5MM | D6: 6MM | E6: 8MM | F6: LAMINA | G6: DOBLES | H6: SOLDADURA | I6: OTRO S | J6: MANO OBRA | K6: COSTO TOTAL | L6: PRECIO VENTA
A7: 0 | B7: 0 | C7: 0 | D7: 0 | E7: 1 | F7: 0 | G7: 0 | H7: 0 | I7: 0 | J7: 0
A8: =A7*A11 -> 0 | B8: =B7*B11 -> 0 | C8: =C7*C11 -> 0 | D8: =D7*D11 -> 0 | E8: =E7*E11 -> 2963.6364 | F8: =F7 -> 0 | G8: =G7*G11 -> 0 | H8: =H7*H11 -> 0 | I8: =I7 -> 0 | J8: =J7 -> 0 | K8: =SUM(A8:J8) -> 2963.6364 | L8: =K8*K11 -> 6520
A10: PRECIO KILO | B10: 8000 | C10: ENDEREZADO | D10: 150 | K10: FACTOR
A11: =(B10+D10)/17.46 -> 466.78121 | B11: =(B10+D10)/9.25 -> 881.08108 | C11: =(B10+D10)/6.1 -> 1336.0656 | D11: =(B10+D10)/4.44 -> 1835.5856 | E11: =(B10+D10)/2.75 -> 2963.6364 | G11: 50 | H11: 50 | K11: 2.2

Sheet Plasticos
A1: VIGENCIA -FEB 2026
A3: Poliestireno Blanco, negro, coextruidos + $900 exteriores + $500 fda alimentos / Reproceso x Kg.=$2.000
A4: Medidas en Mts | C4: Area | D4: Calibre | E4: No. Piezas | F4: Factor | G4: Precio x Kilo | H4: Peso pieza (Kls.) | I4: Peso Total (Kls.) | J4: Precio pieza
A5: Ancho | B5: Largo
A6: 0 | B6: 0 | C6: =B6*A6 -> 0 | D6: 60 | E6: 1 | F6: 2.7 | G6: 16500 | H6: =C6*D6*F6/100 -> 0 | I6: =H6*E6 -> 0 | J6: =C6*D6*F6*G6/100 -> 0
A8: Poliestireno Colores + $900 exteriores + $500 fda alimentos / Reproceso x Kg.=$2.000 / 65% Original=-15%
A9: Medidas en Mts | C9: Area | D9: Calibre | E9: No. Piezas | F9: Factor | G9: Precio x Kilo | H9: Peso pieza (Kls.) | I9: Peso Total (Kls.) | J9: Precio pieza
A10: Ancho | B10: Largo
A11: 0 | B11: 0 | C11: =B11*A11 -> 0 | D11: 60 | E11: 1 | F11: 2.7 | G11: 16500 | H11: =C11*D11*F11/100 -> 0 | I11: =H11*E11 -> 0 | J11: =C11*D11*F11*G11/100 -> 0
A13: Cartonplast / Coroplast / Polipropileno alveolar
A14: Medidas en Mts | C14: Area | D14: Espesor mm | E14: No. Piezas | F14: Gramaje/M2 | G14: Precio x Kilo | H14: Peso pieza (Kls.) | I14: Peso Total (Kls.) | J14: Precio pieza
A15: Ancho | B15: Largo
A16: 1.2 | B16: 2.4 | C16: =B16*A16 -> 2.88 | D16: 5 | E16: 1 | F16: 1500 | G16: 17000 | H16: =C16*F16/1000 -> 4.32 | I16: =H16*E16 -> 4.32 | J16: =H16*G16 -> 73440
A17: PoliestirenoCristal + Resina K
A18: Medidas en Mts | C18: Area | D18: Calibre | E18: No. Piezas | F18: Factor | G18: Precio x Kilo | H18: Peso pieza (Kls.) | I18: Peso Total (Kls.) | J18: Precio pieza
A19: Ancho | B19: Largo
A20: 0 | B20: 0 | C20: =B20*A20 -> 0 | D20: 100 | E20: 1 | F20: 2.7 | G20: 16000 | H20: =C20*D20*F20/100 -> 0 | I20: =H20*E20 -> 0 | J20: =C20*D20*F20*G20/100 -> 0
A22: Poliestireno Black Out
A23: Medidas en Mts | C23: Area | D23: Calibre | E23: No. Piezas | F23: Factor | G23: Precio x Kilo | H23: Peso pieza (Kls.) | I23: Peso Total (Kls.) | J23: Precio pieza
A24: Ancho | B24: Largo
A25: 0 | B25: 0 | C25: =B25*A25 -> 0 | D25: 100 | E25: 1 | F25: 2.7 | G25: 15500 | H25: =C25*D25*F25/100 -> 0 | I25: =H25*E25 -> 0 | J25: =C25*D25*F25*G25/100 -> 0
A27: Polipropileno
A28: Medidas en Mts | C28: Area | D28: Calibre | E28: No. Piezas | F28: Factor | G28: Precio x Kilo | H28: Peso pieza (Kls.) | I28: Peso Total (Kls.) | J28: Precio pieza
A29: Ancho | B29: Largo
A30: 1 | B30: 2 | C30: =B30*A30 -> 2 | D30: 20 | E30: 1 | F30: 2.42 | G30: 12800 | H30: =C30*D30*F30/100 -> 0.968 | I30: =H30*E30 -> 0.968 | J30: =C30*D30*F30*G30/100 -> 12390.4
A32: PET +$500 colores+$1500 plata y dorado+$2000 rojo
A33: Medidas en Mts | C33: Area | D33: Calibre | E33: No. Piezas | F33: Factor | G33: Precio x Kilo | H33: Peso pieza (Kls.) | I33: Peso Total (Kls.) | J33: Precio pieza
A34: Ancho | B34: Largo
A35: 0 | B35: 0 | C35: =B35*A35 -> 0 | D35: 15 | E35: 1 | F35: 3.4 | G35: 800 | H35: =C35*D35*F35/100 -> 0 | I35: =H35*E35 -> 0 | J35: =C35*D35*F35*G35/100 -> 0
A37: PVC (Vipack=10.800 Kg / Vacoplast=9.700 Kg)
A38: Medidas en Mts | C38: Area | D38: Calibre | E38: No. Piezas | F38: Factor | G38: Precio x Kilo | H38: Peso pieza (Kls.) | I38: Peso Total (Kls.) | J38: Precio pieza
A39: Ancho | B39: Largo
A40: 0 | B40: 0 | C40: =B40*A40 -> 0 | D40: 15 | E40: 1 | F40: 3.48 | G40: 12400 | H40: =C40*D40*F40/100 -> 0 | I40: =H40*E40 -> 0 | J40: =C40*D40*F40*G40/100 -> 0
A42: POLIETILENO VIRGEN:$8.000 / RECUPERADO:$5500
A43: Medidas en Mts | C43: Area | D43: Calibre | E43: No. Piezas | F43: Factor | G43: Precio x Kilo | H43: Peso pieza (Kls.) | I43: Peso Total (Kls.) | J43: Precio pieza
A44: Ancho | B44: Largo
A45: 0 | B45: 0 | C45: =B45*A45 -> 0 | D45: 80 | E45: 1 | F45: 2.54 | G45: 9200 | H45: =C45*D45*F45/100 -> 0 | I45: =H45*E45 -> 0 | J45: =C45*D45*F45*G45/100 -> 0
A47: SERVICIO DE TERMOFORMADO POLIESTIRENO
A48: Medidas en Mts | C48: Area | D48: Calibre | E48: Calibre en mm | F48: Densidad Material | G48: Factor de Complejidad | H48: Valores adicionales | I48: TOTAL
A49: Ancho | B49: Largo
...

Sheet Envios, Bodegages, Montajes
A1: Descripcion del producto y/o servicio | D1: Cantidad | E1: Costo unitario (Cop) | F1: Factor | G1: Subtotal venta Unitario (Cop/Usd) | H1: Subtotal venta total (Cop/Usd)
D2: 1 | E2: 0 | F2: 1.3 | G2: =(F2*E2)/$E$9 -> 0 | H2: =G2*D2 -> 0
D3: 1 | E3: 0 | F3: 1.3 | G3: =(F3*E3)/$E$9 -> 0 | H3: =G3*D3 -> 0
D4: 1 | E4: 0 | F4: 1.3 | G4: =(F4*E4)/$E$9 -> 0 | H4: =G4*D4 -> 0
D5: 1 | E5: 0 | F5: 1.3 | G5: =(F5*E5)/$E$9 -> 0 | H5: =G5*D5 -> 0
D6: 1 | E6: 0 | F6: 1.3 | G6: =(F6*E6)/$E$9 -> 0 | H6: =G6*D6 -> 0
D7: 1 | E7: 0 | F7: 1.3 | G7: =(F7*E7)/$E$9 -> 0 | H7: =G7*D7 -> 0
D8: 1 | E8: 0 | F8: 1.3 | G8: =(F8*E8)/$E$9 -> 0 | H8: =G8*D8 -> 0
A9: Si el precio de venta es en Cop el TRM es uno (1) | D9: TRM | E9: 3700 | F9: TOTAL VENTA (Cop o Usd) | H9: =SUM(H2:H8) -> 0
A10: OBSERVACIONES: | F10: 0 | G10: PAGO AL DIA O CON ANTICIPO: | H10: =(H9*F10)+H9 -> 0
F11: 0.03 | G11: PAGO A 30 DIAS | H11: =(H10*F11)+H10 -> 0
F12: 0.06 | G12: PAGO A 60 DIAS | H12: =(H11*F12)+H11 -> 0
A14: http://www.enviacolvanes.com.co/
A15: http://www.tcc.com.co/
A16: https://www.interrapidisimo.com/cotiza-tu-envio/
A17: https://www.mudango.com/

Sheet Hoja1
